<?xml version="1.0"?>
<robot name="test">
  <link name="base_link">
    <visual>
      <geometry>
        <cylinder length="0.6" radius="0.2"/>
      </geometry>
      <material name="blue">
        <color rgba="0 0 .8 1"/>
      </material>
    </visual>
  </link>

  <link name="med">
    <visual>
      <geometry>
        <box size="0.2 .2 .1"/>
      </geometry>
      <origin rpy="0 1.57075 0" xyz="0 0 0.1"/>
      <material name="white">
        <color rgba="1 1 1 1"/>
      </material>
    </visual>
  </link>

  <joint name="InfJoint" type="revolute">
    <axis xyz="0 0 1"/>
    <limit effort="1000.0" lower="0.0" upper="3.141592654" velocity="0.001"/>
    <parent link="base_link"/>
    <child link="med"/>
    <origin xyz="0 0 0.3" />
  </joint>

  <link name="sup">
    <visual>
      <geometry>
        <box size="0.2 .2 .1"/>
      </geometry>
      <origin rpy="0 1.57075 0" xyz="0 0 0.1"/>
      <material name="xx">
        <color rgba="0 0.5 0 1"/>
      </material>
    </visual>
  </link>

  <joint name="SupJoint" type="revolute">
    <axis xyz="0 -1 0"/>
    <limit effort="1000.0" lower="0.0" upper="3.141592654" velocity="0.001"/>
    <parent link="med"/>
    <child link="sup"/>
    <origin xyz="0 0 0.2" rpy="0 2.35619449 0"/>
  </joint>

</robot>
